<?xml version="1.0"?>
<robot name="robot_name">
    <link name="link_name">
        <visual>
            <geometry>
                <mesh filename="package://pkg_name/meshes/file_name"/>
                <box size="1.0 1.0 1.0" />
                <cylinder radius="1.0" length="1.0"/>
            </geometry>
            <material name="LightGrey">
                <color rgba="0.7 0.7 0.7 1.0"/>
            </material>
        </visual>
        <collision>
            <geometry>
                <mesh filename="package://pkg_name/meshes/file_name"/>
                <box size="1.0 1.0 1.0" />
                <cylinder radius="1.0" length="1.0"/>
            </geometry>
        </collision>
        <inertial>
            <mass value="0.0"/>
            <origin xyz="0.0 0.0 0.0" rpy="0.0 0.0 0.0"/>
            <inertia ixx="0.0" ixy="0.0" ixz="0.0" iyy="0.0" iyz="0.0" izz="0.0"/>
        </inertial>
    </link>
    <joint name="joint_name" type="prismatic">
        <parent link="parent_link"/>
        <child link="child_link"/>
        <axis xyz="0 0 0"/>
        <limit lower="-0.5" upper="0.5" velocity="0.5" effort="1000.0"/>
        <origin xyz="0 0 0" rpy="0 0 0"/>
    </joint>
    
</robot>