<robot name="bd_robot">

<link name="world_link"/>

<!-- link_world to link_base joint -->
    <joint name="world_to_rotx_joint" type="revolute">
         <parent link="world_link"/>
         <child link="rotx_link"/>
         <origin xyz="0.0 0.0 0.0" rpy="0.0 0.0 0.0"/>
         <axis xyz="1 0 0"/>

         <limit lower="-1.5" upper="1.5" velocity="0.5" effort="1000.0"/>
    </joint>

    <link name="rotx_link"/>

    <joint name="rotx_to_roty_joint" type="revolute">
        <parent link="rotx_link"/>
        <child link="roty_link"/>
        <axis xyz="0 1 0"/>
        <limit lower="-3.14159" upper="3.14159" velocity="50.0" effort="1000.0"/>
        <origin xyz="0 0 0" rpy="0 0 0"/>
    </joint>

    <link name="roty_link"/>

    <joint name="roty_to_rotz_joint" type="revolute">
        <parent link="roty_link"/>
        <child link="rotz_link"/>
        <axis xyz="0 0 1"/>
        <limit lower="-3.14159" upper="3.14159" velocity="50.0" effort="1000.0"/>
        <origin xyz="0 0 0" rpy="0 0 0"/>
    </joint>

    <link name="rotz_link"/>

    <joint name="rotz_to_base_link" type="fixed">
        <parent link="rotz_link"/>
        <child link="base_link"/>
        <origin xyz="0.0 0.0 0.0" rpy="0.0 0.0 0.0"/>
    </joint>
    
    
    
    
    
    
    
    
    

<!-- base_link -->
   <link name="base_link">
    <inertial>
        <origin xyz="0.0 0.0 0.0" rpy="0.0 0.0 0.0"/>
        <mass value="0.0"/>
        <inertia ixx="0.0" ixy="0.0" ixz="0.0" iyy="0.0" iyz="0.0" izz="0.0"/>
    </inertial>
    <visual name="">
        <origin xyz="0.0 0.0 0.0" rpy="0.0 0.0 0.0"/>
        <geometry>
            <box size="2.0 3.0 1.0"/>
        </geometry>
        <material name="">
            <color rgba="1.0 0.0 0.0 1.0"/>
            <texture filename=""/>
        </material>
    </visual>
    <collision>
        <origin xyz="0.0 0.0 0.0" rpy="0.0 0.0 0.0"/>
        <geometry>
            <box size="0.0 0.0 0.0"/>
        </geometry>
    </collision>
   </link>

<!-- base_link to right_front_link joint-->
    <joint name="base_to_wheel_rf_joint" type="continuous">
        <origin xyz="1.3 1.2 0.0" rpy="0.0 1.57 0.0"/>
        <parent link="base_link"/>
        <child link="wheel_rf_link"/>
        <axis xyz="0 0 1"/>
    </joint>
    
<!-- right_front_link -->
    <link name="wheel_rf_link">
        <inertial>
            <origin xyz="0.0 0.0 0.0" rpy="0.0 0.0 0.0"/>
            <mass value="0.0"/>
            <inertia ixx="0.0" ixy="0.0" ixz="0.0" iyy="0.0" iyz="0.0" izz="0.0"/>
        </inertial>
        <visual name="">
            <origin xyz="0.0 0.0 0.0" rpy="0.0 0.0 0.0"/>
            <geometry>
                <cylinder radius="0.7" length="0.4"/>
            </geometry>
            <material name="purple">
                <color rgba="1.0 0.0 1.0 1.0"/>
                <texture filename=""/>
            </material>
        </visual>
        <collision>
            <origin xyz="0.0 0.0 0.0" rpy="0.0 0.0 0.0"/>
            <geometry>
                <cylinder radius="0.7" length="0.4"/>
            </geometry>
        </collision>
    </link>

<!-- base_link to left_front_link joint-->
    <joint name="base_to_wheel_lf_joint" type="continuous">
        <origin xyz="-1.3 1.2 0.0" rpy="0.0 1.57 0.0"/>
        <parent link="base_link"/>
        <child link="wheel_lf_link"/>
        <axis xyz="0 0 1"/>
    </joint>
    

<!-- left_front_link -->
    <link name="wheel_lf_link">
        <inertial>
            <origin xyz="0.0 0.0 0.0" rpy="0.0 0.0 0.0"/>
            <mass value="0.0"/>
            <inertia ixx="0.0" ixy="0.0" ixz="0.0" iyy="0.0" iyz="0.0" izz="0.0"/>
        </inertial>
        <visual name="">
            <origin xyz="0.0 0.0 0.0" rpy="0.0 0.0 0.0"/>
            <geometry>
                <cylinder radius="0.7" length="0.4"/>
            </geometry>
            <material name="purple">
                <color rgba="1.0 0.0 1.0 1.0"/>
                <texture filename=""/>
            </material>
        </visual>
        <collision>
            <origin xyz="0.0 0.0 0.0" rpy="0.0 0.0 0.0"/>
            <geometry>
                <cylinder radius="0.7" length="0.4"/>
            </geometry>
        </collision>
    </link>



<!-- base_link to right_rear_link joint-->
    <joint name="base_to_wheel_rr_joint" type="continuous">
        <origin xyz="1.3 -1.2 0.0" rpy="0.0 1.57 0.0"/>
        <parent link="base_link"/>
        <child link="wheel_rr_link"/>
        <axis xyz="0 0 1"/>
    </joint>
    
<!-- right_rear_link -->
    <link name="wheel_rr_link">
        <inertial>
            <origin xyz="0.0 0.0 0.0" rpy="0.0 0.0 0.0"/>
            <mass value="0.0"/>
            <inertia ixx="0.0" ixy="0.0" ixz="0.0" iyy="0.0" iyz="0.0" izz="0.0"/>
        </inertial>
        <visual name="">
            <origin xyz="0.0 0.0 0.0" rpy="0.0 0.0 0.0"/>
            <geometry>
                <cylinder radius="0.7" length="0.4"/>
            </geometry>
            <material name="purple">
                <color rgba="1.0 0.0 1.0 1.0"/>
                <texture filename=""/>
            </material>
        </visual>
        <collision>
            <origin xyz="0.0 0.0 0.0" rpy="0.0 0.0 0.0"/>
            <geometry>
                <cylinder radius="0.7" length="0.4"/>
            </geometry>
        </collision>
    </link>

<!-- base_link to left_rear_link joint-->
    <joint name="base_to_wheel_lr_joint" type="continuous">
        <origin xyz="-1.3 -1.2 0.0" rpy="0.0 1.57 0.0"/>
        <parent link="base_link"/>
        <child link="wheel_lr_link"/>
        <axis xyz="0 0 1"/>
    </joint>
    

<!-- left_rear_link -->
    <link name="wheel_lr_link">
        <inertial>
            <origin xyz="0.0 0.0 0.0" rpy="0.0 0.0 0.0"/>
            <mass value="0.0"/>
            <inertia ixx="0.0" ixy="0.0" ixz="0.0" iyy="0.0" iyz="0.0" izz="0.0"/>
        </inertial>
        <visual name="">
            <origin xyz="0.0 0.0 0.0" rpy="0.0 0.0 0.0"/>
            <geometry>
                <cylinder radius="0.7" length="0.4"/>
            </geometry>
            <material name="purple">
                <color rgba="1.0 0.0 1.0 1.0"/>
                <texture filename=""/>
            </material>
        </visual>
        <collision>
            <origin xyz="0.0 0.0 0.0" rpy="0.0 0.0 0.0"/>
            <geometry>
                <cylinder radius="0.7" length="0.4"/>
            </geometry>
        </collision>
    </link>




</robot>